huiyu@huiyu-linux2:~$ conda create --name unsloth_env_2 python=3.11pytorch-cuda=12.1 pytorch cudatoolkit xformers -c pytorch -c nvidia -c xformers -y
Channels:
 - pytorch
 - nvidia
 - xformers
 - defaults
Platform: linux-64
Collecting package metadata (repodata.json): - Retrying (Retry(total=2, connect=None, read=None, redirect=None, status=None)) after connection broken by 'SSLCertVerificationError(1, '[SSL: CERTIFICATE_VERIFY_FAILED] certificate verify failed: self-signed certificate in certificate chain (_ssl.c:1028)')': /pkgs/main/linux-64/repodata.json.zst

\ Retrying (Retry(total=2, connect=None, read=None, redirect=None, status=None)) after connection broken by 'SSLCertVerificationError(1, '[SSL: CERTIFICATE_VERIFY_FAILED] certificate verify failed: self-signed certificate in certificate chain (_ssl.c:1028)')': /nvidia/linux-64/repodata.json.zst

Retrying (Retry(total=2, connect=None, read=None, redirect=None, status=None)) after connection broken by 'SSLCertVerificationError(1, '[SSL: CERTIFICATE_VERIFY_FAILED] certificate verify failed: self-signed certificate in certificate chain (_ssl.c:1028)')': /xformers/noarch/repodata.json.zst

Retrying (Retry(total=2, connect=None, read=None, redirect=None, status=None)) after connection broken by 'SSLCertVerificationError(1, '[SSL: CERTIFICATE_VERIFY_FAILED] certificate verify failed: self-signed certificate in certificate chain (_ssl.c:1028)')': /xformers/linux-64/repodata.json.zst

Retrying (Retry(total=2, connect=None, read=None, redirect=None, status=None)) after connection broken by 'SSLCertVerificationError(1, '[SSL: CERTIFICATE_VERIFY_FAILED] certificate verify failed: self-signed certificate in certificate chain (_ssl.c:1028)')': /nvidia/noarch/repodata.json.zst

Retrying (Retry(total=2, connect=None, read=None, redirect=None, status=None)) after connection broken by 'SSLCertVerificationError(1, '[SSL: CERTIFICATE_VERIFY_FAILED] certificate verify failed: self-signed certificate in certificate chain (_ssl.c:1028)')': /pytorch/noarch/repodata.json.zst

Retrying (Retry(total=2, connect=None, read=None, redirect=None, status=None)) after connection broken by 'SSLCertVerificationError(1, '[SSL: CERTIFICATE_VERIFY_FAILED] certificate verify failed: self-signed certificate in certificate chain (_ssl.c:1028)')': /pkgs/main/noarch/repodata.json.zst

Retrying (Retry(total=2, connect=None, read=None, redirect=None, status=None)) after connection broken by 'SSLCertVerificationError(1, '[SSL: CERTIFICATE_VERIFY_FAILED] certificate verify failed: self-signed certificate in certificate chain (_ssl.c:1028)')': /pytorch/linux-64/repodata.json.zst

Retrying (Retry(total=2, connect=None, read=None, redirect=None, status=None)) after connection broken by 'SSLCertVerificationError(1, '[SSL: CERTIFICATE_VERIFY_FAILED] certificate verify failed: self-signed certificate in certificate chain (_ssl.c:1028)')': /pkgs/r/noarch/repodata.json.zst

Retrying (Retry(total=2, connect=None, read=None, redirect=None, status=None)) after connection broken by 'SSLCertVerificationError(1, '[SSL: CERTIFICATE_VERIFY_FAILED] certificate verify failed: self-signed certificate in certificate chain (_ssl.c:1028)')': /pkgs/r/linux-64/repodata.json.zst

\ Retrying (Retry(total=1, connect=None, read=None, redirect=None, status=None)) after connection broken by 'SSLCertVerificationError(1, '[SSL: CERTIFICATE_VERIFY_FAILED] certificate verify failed: self-signed certificate in certificate chain (_ssl.c:1028)')': /pkgs/main/linux-64/repodata.json.zst

| Retrying (Retry(total=1, connect=None, read=None, redirect=None, status=None)) after connection broken by 'SSLCertVerificationError(1, '[SSL: CERTIFICATE_VERIFY_FAILED] certificate verify failed: self-signed certificate in certificate chain (_ssl.c:1028)')': /nvidia/linux-64/repodata.json.zst

Retrying (Retry(total=1, connect=None, read=None, redirect=None, status=None)) after connection broken by 'SSLCertVerificationError(1, '[SSL: CERTIFICATE_VERIFY_FAILED] certificate verify failed: self-signed certificate in certificate chain (_ssl.c:1028)')': /xformers/noarch/repodata.json.zst

Retrying (Retry(total=1, connect=None, read=None, redirect=None, status=None)) after connection broken by 'SSLCertVerificationError(1, '[SSL: CERTIFICATE_VERIFY_FAILED] certificate verify failed: self-signed certificate in certificate chain (_ssl.c:1028)')': /pkgs/r/linux-64/repodata.json.zst

Retrying (Retry(total=1, connect=None, read=None, redirect=None, status=None)) after connection broken by 'SSLCertVerificationError(1, '[SSL: CERTIFICATE_VERIFY_FAILED] certificate verify failed: self-signed certificate in certificate chain (_ssl.c:1028)')': /pytorch/linux-64/repodata.json.zst

/ Retrying (Retry(total=1, connect=None, read=None, redirect=None, status=None)) after connection broken by 'SSLCertVerificationError(1, '[SSL: CERTIFICATE_VERIFY_FAILED] certificate verify failed: self-signed certificate in certificate chain (_ssl.c:1028)')': /pkgs/r/noarch/repodata.json.zst

Retrying (Retry(total=1, connect=None, read=None, redirect=None, status=None)) after connection broken by 'SSLCertVerificationError(1, '[SSL: CERTIFICATE_VERIFY_FAILED] certificate verify failed: self-signed certificate in certificate chain (_ssl.c:1028)')': /nvidia/noarch/repodata.json.zst

Retrying (Retry(total=1, connect=None, read=None, redirect=None, status=None)) after connection broken by 'SSLCertVerificationError(1, '[SSL: CERTIFICATE_VERIFY_FAILED] certificate verify failed: self-signed certificate in certificate chain (_ssl.c:1028)')': /pkgs/main/noarch/repodata.json.zst

- Retrying (Retry(total=1, connect=None, read=None, redirect=None, status=None)) after connection broken by 'SSLCertVerificationError(1, '[SSL: CERTIFICATE_VERIFY_FAILED] certificate verify failed: self-signed certificate in certificate chain (_ssl.c:1028)')': /pytorch/noarch/repodata.json.zst

| Retrying (Retry(total=1, connect=None, read=None, redirect=None, status=None)) after connection broken by 'SSLCertVerificationError(1, '[SSL: CERTIFICATE_VERIFY_FAILED] certificate verify failed: self-signed certificate in certificate chain (_ssl.c:1028)')': /xformers/linux-64/repodata.json.zst

| Retrying (Retry(total=0, connect=None, read=None, redirect=None, status=None)) after connection broken by 'SSLCertVerificationError(1, '[SSL: CERTIFICATE_VERIFY_FAILED] certificate verify failed: self-signed certificate in certificate chain (_ssl.c:1028)')': /nvidia/linux-64/repodata.json.zst

Retrying (Retry(total=0, connect=None, read=None, redirect=None, status=None)) after connection broken by 'SSLCertVerificationError(1, '[SSL: CERTIFICATE_VERIFY_FAILED] certificate verify failed: self-signed certificate in certificate chain (_ssl.c:1028)')': /xformers/noarch/repodata.json.zst

/ Retrying (Retry(total=0, connect=None, read=None, redirect=None, status=None)) after connection broken by 'SSLCertVerificationError(1, '[SSL: CERTIFICATE_VERIFY_FAILED] certificate verify failed: self-signed certificate in certificate chain (_ssl.c:1028)')': /pkgs/main/linux-64/repodata.json.zst

Retrying (Retry(total=0, connect=None, read=None, redirect=None, status=None)) after connection broken by 'SSLCertVerificationError(1, '[SSL: CERTIFICATE_VERIFY_FAILED] certificate verify failed: self-signed certificate in certificate chain (_ssl.c:1028)')': /pytorch/linux-64/repodata.json.zst

- Retrying (Retry(total=0, connect=None, read=None, redirect=None, status=None)) after connection broken by 'SSLCertVerificationError(1, '[SSL: CERTIFICATE_VERIFY_FAILED] certificate verify failed: self-signed certificate in certificate chain (_ssl.c:1028)')': /pkgs/r/noarch/repodata.json.zst

Retrying (Retry(total=0, connect=None, read=None, redirect=None, status=None)) after connection broken by 'SSLCertVerificationError(1, '[SSL: CERTIFICATE_VERIFY_FAILED] certificate verify failed: self-signed certificate in certificate chain (_ssl.c:1028)')': /nvidia/noarch/repodata.json.zst

\ Retrying (Retry(total=0, connect=None, read=None, redirect=None, status=None)) after connection broken by 'SSLCertVerificationError(1, '[SSL: CERTIFICATE_VERIFY_FAILED] certificate verify failed: self-signed certificate in certificate chain (_ssl.c:1028)')': /pytorch/noarch/repodata.json.zst

Retrying (Retry(total=0, connect=None, read=None, redirect=None, status=None)) after connection broken by 'SSLCertVerificationError(1, '[SSL: CERTIFICATE_VERIFY_FAILED] certificate verify failed: self-signed certificate in certificate chain (_ssl.c:1028)')': /pkgs/main/noarch/repodata.json.zst

Retrying (Retry(total=0, connect=None, read=None, redirect=None, status=None)) after connection broken by 'SSLCertVerificationError(1, '[SSL: CERTIFICATE_VERIFY_FAILED] certificate verify failed: self-signed certificate in certificate chain (_ssl.c:1028)')': /pkgs/r/linux-64/repodata.json.zst

/ Retrying (Retry(total=0, connect=None, read=None, redirect=None, status=None)) after connection broken by 'SSLCertVerificationError(1, '[SSL: CERTIFICATE_VERIFY_FAILED] certificate verify failed: self-signed certificate in certificate chain (_ssl.c:1028)')': /xformers/linux-64/repodata.json.zst

failed

CondaSSLError: Encountered an SSL error. Most likely a certificate verification issue.

Exception: HTTPSConnectionPool(host='conda.anaconda.org', port=443): Max retries exceeded with url: /pytorch/linux-64/repodata.json.zst (Caused by SSLError(SSLCertVerificationError(1, '[SSL: CERTIFICATE_VERIFY_FAILED] certificate verify failed: self-signed certificate in certificate chain (_ssl.c:1028)')))


